<?xml version="1.0" encoding="utf-8" ?>

<robot name="ur16e_robot">

    <transmission name="shoulder_pan_trans">
        <type>transmission_interface/SimpleTransmission</type>
        <joint name="shoulder_pan_joint">
            <hardwareInterface>hardware_interface/PositionJointInterface</hardwareInterface>
        </joint>
        <actuator name="shoulder_pan_motor">
            <mechanicalReduction>1</mechanicalReduction>
        </actuator>
    </transmission>
    <transmission name="shoulder_lift_trans">
        <type>transmission_interface/SimpleTransmission</type>
        <joint name="shoulder_lift_joint">
            <hardwareInterface>hardware_interface/PositionJointInterface</hardwareInterface>
        </joint>
        <actuator name="shoulder_lift_motor">
            <mechanicalReduction>1</mechanicalReduction>
        </actuator>
    </transmission>
    <transmission name="elbow_trans">
        <type>transmission_interface/SimpleTransmission</type>
        <joint name="elbow_joint">
            <hardwareInterface>hardware_interface/PositionJointInterface</hardwareInterface>
        </joint>
        <actuator name="elbow_motor">
            <mechanicalReduction>1</mechanicalReduction>
        </actuator>
    </transmission>
    <transmission name="wrist_1_trans">
        <type>transmission_interface/SimpleTransmission</type>
        <joint name="wrist_1_joint">
            <hardwareInterface>hardware_interface/PositionJointInterface</hardwareInterface>
        </joint>
        <actuator name="wrist_1_motor">
            <mechanicalReduction>1</mechanicalReduction>
        </actuator>
    </transmission>
    <transmission name="wrist_2_trans">
        <type>transmission_interface/SimpleTransmission</type>
        <joint name="wrist_2_joint">
            <hardwareInterface>hardware_interface/PositionJointInterface</hardwareInterface>
        </joint>
        <actuator name="wrist_2_motor">
            <mechanicalReduction>1</mechanicalReduction>
        </actuator>
    </transmission>
    <transmission name="wrist_3_trans">
        <type>transmission_interface/SimpleTransmission</type>
        <joint name="wrist_3_joint">
            <hardwareInterface>hardware_interface/PositionJointInterface</hardwareInterface>
        </joint>
        <actuator name="wrist_3_motor">
            <mechanicalReduction>1</mechanicalReduction>
        </actuator>
    </transmission>
    <!-- links: main serial chain -->
    <link name="world" />
    <link name="base_link" />
    <link name="base_link_inertia">
        <visual>
            <origin rpy="0 0 3.14159265359" xyz="0 0 0" />
            <geometry>
                <mesh filename="package://ur_description/meshes/ur10e/visual/base.dae" />
            </geometry>
            <material name="LightGrey">
                <color rgba="0.7 0.7 0.7 1.0" />
            </material>
        </visual>
        <collision>
            <origin rpy="0 0 3.14159265359" xyz="0 0 0" />
            <geometry>
                <mesh filename="package://ur_description/meshes/ur10e/collision/base.stl" />
            </geometry>
        </collision>
        
<inertial>
            <mass value="4.0" />
            <origin rpy="0 0 0" xyz="0 0 0" />
            <inertia ixx="0.0061063308908" ixy="0.0" ixz="0.0" iyy="0.0061063308908" iyz="0.0" izz="0.01125" />
        </inertial>

    </link>
    <link name="shoulder_link">
        <visual>
            <origin rpy="0 0 3.14159265359" xyz="0 0 0" />
            <geometry>
                <mesh filename="package://ur_description/meshes/ur10e/visual/shoulder.dae" />
            </geometry>
            <material name="LightGrey">
                <color rgba="0.7 0.7 0.7 1.0" />
            </material>
        </visual>
        <collision>
            <origin rpy="0 0 3.14159265359" xyz="0 0 0" />
            <geometry>
                <mesh filename="package://ur_description/meshes/ur10e/collision/shoulder.stl" />
            </geometry>
        </collision>
        
<inertial>
            <mass value="7.369" />
            <origin rpy="0 0 0" xyz="0 0 0" />
            <inertia ixx="0.03351" ixy="0.00002" ixz="-0.00001" iyy="0.03374" iyz="0.00374" izz="0.0207253125" />
        </inertial>

    </link>
    <link name="upper_arm_link">
        <visual>
            <origin rpy="1.57079632679 0 -1.57079632679" xyz="0 0 0.176" />
            <geometry>
                <mesh filename="package://ur_description/meshes/ur16e/visual/upperarm.dae" />
            </geometry>
            <material name="LightGrey">
                <color rgba="0.7 0.7 0.7 1.0" />
            </material>
        </visual>
        <collision>
            <origin rpy="1.57079632679 0 -1.57079632679" xyz="0 0 0.176" />
            <geometry>
                <mesh filename="package://ur_description/meshes/ur16e/collision/upperarm.stl" />
            </geometry>
        </collision>
        
<inertial>
            <mass value="10.45" />
            <origin rpy="0 1.57079632679 0" xyz="-0.2392 0.0 0.175" />
            <inertia ixx="0.02796" ixy="-0.0001" ixz="-0.0072" iyy="0.47558" iyz="0.00003" izz="0.47635" />
        </inertial>

    </link>
    <link name="forearm_link">
        <visual>
            <origin rpy="1.57079632679 0 -1.57079632679" xyz="0 0 0.04" />
            <geometry>
                <mesh filename="package://ur_description/meshes/ur16e/visual/forearm.dae" />
            </geometry>
            <material name="LightGrey">
                <color rgba="0.7 0.7 0.7 1.0" />
            </material>
        </visual>
        <collision>
            <origin rpy="1.57079632679 0 -1.57079632679" xyz="0 0 0.04" />
            <geometry>
                <mesh filename="package://ur_description/meshes/ur16e/collision/forearm.stl" />
            </geometry>
        </collision>
        
<inertial>
            <mass value="4.321" />
            <origin rpy="0 1.57079632679 0" xyz="-0.18 0.0 0.04" />
            <inertia ixx="0.01091" ixy="0.00006" ixz="0.01012" iyy="0.12060" iyz="0.00001" izz="0.11714" />
        </inertial>

    </link>
    <link name="wrist_1_link">
        <visual>
            <origin rpy="1.57079632679 0 0" xyz="0 0 -0.135" />
            <geometry>
                <mesh filename="package://ur_description/meshes/ur10e/visual/wrist1.dae" />
            </geometry>
            <material name="LightGrey">
                <color rgba="0.7 0.7 0.7 1.0" />
            </material>
        </visual>
        <collision>
            <origin rpy="1.57079632679 0 0" xyz="0 0 -0.135" />
            <geometry>
                <mesh filename="package://ur_description/meshes/ur10e/collision/wrist1.stl" />
            </geometry>
        </collision>
        
<inertial>
            <mass value="2.18" />
            <origin rpy="0 0 0" xyz="0 0 0" />
            <inertia ixx="0.00568162272735" ixy="-0.00001" ixz="0.0" iyy="0.00245" iyz="0.00083" izz="0.00579" />
        </inertial>

    </link>
    <link name="wrist_2_link">
        <visual>
            <origin rpy="0 0 0" xyz="0 0 -0.12" />
            <geometry>
                <mesh filename="package://ur_description/meshes/ur10e/visual/wrist2.dae" />
            </geometry>
            <material name="LightGrey">
                <color rgba="0.7 0.7 0.7 1.0" />
            </material>
        </visual>
        <collision>
            <origin rpy="0 0 0" xyz="0 0 -0.12" />
            <geometry>
                <mesh filename="package://ur_description/meshes/ur10e/collision/wrist2.stl" />
            </geometry>
        </collision>
        
<inertial>
            <mass value="2.033" />
            <origin rpy="0 0 0" xyz="0 0 0" />
            <inertia ixx="0.00389" ixy="0.00001" ixz="0.0" iyy="0.00219" iyz="-0.00045" izz="0.00363" />
        </inertial>

    </link>
    <link name="wrist_3_link">
        <visual>
            <origin rpy="1.57079632679 0 0" xyz="0 0 -0.1168" />
            <geometry>
                <mesh filename="package://ur_description/meshes/ur10e/visual/wrist3.dae" />
            </geometry>
            <material name="LightGrey">
                <color rgba="0.7 0.7 0.7 1.0" />
            </material>
        </visual>
        <collision>
            <origin rpy="1.57079632679 0 0" xyz="0 0 -0.1168" />
            <geometry>
                <mesh filename="package://ur_description/meshes/ur10e/collision/wrist3.stl" />
            </geometry>
        </collision>
        
<inertial>
            <mass value="0.907" />
            <origin rpy="0 0 0" xyz="0.0 0.0 -0.025" />
            <inertia ixx="0.00117" ixy="0.0" ixz="0.0" iyy="0.00118" iyz="0.0" izz="0.00084" />
        </inertial>

    </link>
    <!-- joints: main serial chain -->

    <joint name="world-base_link" type="fixed">
        <parent link="world" />
        <child link="base_link" />
        <origin rpy="0 0 0" xyz="0 0 0"/>
    </joint>

    <joint name="base_link-base_link_inertia" type="fixed">
        <parent link="base_link" />
        <child link="base_link_inertia" />
        <!-- 'base_link' is REP-103 aligned (so X+ forward), while the internal
           frames of the robot/controller have X+ pointing backwards.
           Use the joint between 'base_link' and 'base_link_inertia' (a dummy
           link/frame) to introduce the necessary rotation over Z (of pi rad).
      -->
        <origin rpy="0 0 3.14159265359" xyz="0 0 0" />
    </joint>
    <joint name="shoulder_pan_joint" type="revolute">
        <parent link="base_link_inertia" />
        <child link="shoulder_link" />
        <origin rpy="0 0 0" xyz="0 0 0.1807" />
        <axis xyz="0 0 1" />
        <limit effort="330.0" lower="-6.28318530718" upper="6.28318530718" velocity="2.09439510239" />
        <dynamics damping="0" friction="0" />
    </joint>
    <joint name="shoulder_lift_joint" type="revolute">
        <parent link="shoulder_link" />
        <child link="upper_arm_link" />
        <origin rpy="1.570796327 0 0" xyz="0 0 0" />
        <axis xyz="0 0 1" />
        <limit effort="330.0" lower="-3.14159265359" upper="3.14159265359" velocity="2.09439510239" />
        <dynamics damping="0" friction="0" />
    </joint>
    <joint name="elbow_joint" type="revolute">
        <parent link="upper_arm_link" />
        <child link="forearm_link" />
        <origin rpy="0 0 0" xyz="-0.4784 0 0" />
        <axis xyz="0 0 1" />
        <limit effort="150.0" lower="-3.14159265359" upper="3.14159265359" velocity="3.14159265359" />
        <dynamics damping="0" friction="0" />
    </joint>
    <joint name="wrist_1_joint" type="revolute">
        <parent link="forearm_link" />
        <child link="wrist_1_link" />
        <origin rpy="0 0 0" xyz="-0.36 0 0.17415" />
        <axis xyz="0 0 1" />
        <limit effort="56.0" lower="-3.14159265359" upper="3.14159265359" velocity="3.14159265359" />
        <dynamics damping="0" friction="0" />
    </joint>
    <joint name="wrist_2_joint" type="revolute">
        <parent link="wrist_1_link" />
        <child link="wrist_2_link" />
        <origin rpy="1.570796327 0 0" xyz="0 -0.11985 -2.45816459076e-11" />
        <axis xyz="0 0 1" />
        <limit effort="56.0" lower="-3.14159265359" upper="3.14159265359" velocity="3.14159265359" />
        <dynamics damping="0" friction="0" />
    </joint>
    <joint name="wrist_3_joint" type="revolute">
        <parent link="wrist_2_link" />
        <child link="wrist_3_link" />
        <origin rpy="1.57079632659 3.14159265359 3.14159265359" xyz="0 0.11655 -2.39048045935e-11" />
        <axis xyz="0 0 1" />
        <limit effort="56.0" lower="-3.14159265359" upper="3.14159265359" velocity="3.14159265359" />
        <dynamics damping="0" friction="0" />
    </joint>
    <!-- ROS-Industrial 'base' frame: base_link to UR 'Base' Coordinates transform -->
    <link name="base" />
    <joint name="base_link-base_fixed_joint" type="fixed">
        <!-- Note the rotation over Z of pi radians: as base_link is REP-103
           aligned (ie: has X+ forward, Y+ left and Z+ up), this is needed
           to correctly align 'base' with the 'Base' coordinate system of
           the UR controller.
      -->
        <origin rpy="0 0 3.14159265359" xyz="0 0 0" />
        <parent link="base_link" />
        <child link="base" />
    </joint>
    <!-- ROS-Industrial 'flange' frame: attachment point for EEF models -->
    <link name="flange" />
    <joint name="wrist_3-flange" type="fixed">
        <parent link="wrist_3_link" />
        <child link="flange" />
        <origin rpy="0 -1.57079632679 -1.57079632679" xyz="0 0 0" />
    </joint>
    <!-- ROS-Industrial 'tool0' frame: all-zeros tool frame -->
    <link name="tool0" />
    <joint name="flange-tool0" type="fixed">
        <!-- default toolframe: X+ left, Y+ up, Z+ front -->
        <origin rpy="1.57079632679 0 1.57079632679" xyz="0 0 0" />
        <parent link="flange" />
        <child link="tool0" />
    </joint>
    <transmission name="trans_shoulder_pan_joint">
        <type>transmission_interface/SimpleTransmission</type>
        <joint name="shoulder_pan_joint">
            <hardwareInterface>hardware_interface/EffortJointInterface</hardwareInterface>
        </joint>
        <actuator name="shoulder_pan_joint_motor">
            <hardwareInterface>hardware_interface/EffortJointInterface</hardwareInterface>
            <mechanicalReduction>1</mechanicalReduction>
        </actuator>
    </transmission>
    <transmission name="trans_shoulder_lift_joint">
        <type>transmission_interface/SimpleTransmission</type>
        <joint name="shoulder_lift_joint">
            <hardwareInterface>hardware_interface/EffortJointInterface</hardwareInterface>
        </joint>
        <actuator name="shoulder_lift_joint_motor">
            <hardwareInterface>hardware_interface/EffortJointInterface</hardwareInterface>
            <mechanicalReduction>1</mechanicalReduction>
        </actuator>
    </transmission>
    <transmission name="trans_elbow_joint">
        <type>transmission_interface/SimpleTransmission</type>
        <joint name="elbow_joint">
            <hardwareInterface>hardware_interface/EffortJointInterface</hardwareInterface>
        </joint>
        <actuator name="elbow_joint_motor">
            <hardwareInterface>hardware_interface/EffortJointInterface</hardwareInterface>
            <mechanicalReduction>1</mechanicalReduction>
        </actuator>
    </transmission>
    <transmission name="trans_wrist_1_joint">
        <type>transmission_interface/SimpleTransmission</type>
        <joint name="wrist_1_joint">
            <hardwareInterface>hardware_interface/EffortJointInterface</hardwareInterface>
        </joint>
        <actuator name="wrist_1_joint_motor">
            <hardwareInterface>hardware_interface/EffortJointInterface</hardwareInterface>
            <mechanicalReduction>1</mechanicalReduction>
        </actuator>
    </transmission>
    <transmission name="trans_wrist_2_joint">
        <type>transmission_interface/SimpleTransmission</type>
        <joint name="wrist_2_joint">
            <hardwareInterface>hardware_interface/EffortJointInterface</hardwareInterface>
        </joint>
        <actuator name="wrist_2_joint_motor">
            <hardwareInterface>hardware_interface/EffortJointInterface</hardwareInterface>
            <mechanicalReduction>1</mechanicalReduction>
        </actuator>
    </transmission>
    <transmission name="trans_wrist_3_joint">
        <type>transmission_interface/SimpleTransmission</type>
        <joint name="wrist_3_joint">
            <hardwareInterface>hardware_interface/EffortJointInterface</hardwareInterface>
        </joint>
        <actuator name="wrist_3_joint_motor">
            <hardwareInterface>hardware_interface/EffortJointInterface</hardwareInterface>
            <mechanicalReduction>1</mechanicalReduction>
        </actuator>
    </transmission>
    <gazebo>
        <plugin name="gazebo_ros_control" filename="libgazebo_ros_control.so">
            <robotNamespace>/ur16e</robotNamespace>
        </plugin>
    </gazebo>
</robot>
